<?xml version="1.0" encoding="UTF-8"?>
<testng-results skipped="0" failed="1" ignored="0" total="3" passed="2">
  <reporter-output>
  </reporter-output>
  <suite name="Default suite" duration-ms="427" started-at="2019-11-07T23:05:05 IST" finished-at="2019-11-07T23:05:05 IST">
    <groups>
    </groups>
    <test name="Default test" duration-ms="427" started-at="2019-11-07T23:05:05 IST" finished-at="2019-11-07T23:05:05 IST">
      <class name="week4.day4.LearnTestNGAssert">
        <test-method status="FAIL" signature="testCase1()[pri:0, instance:week4.day4.LearnTestNGAssert@b8a058]" name="testCase1" duration-ms="93" started-at="2019-11-07T23:05:05 IST" finished-at="2019-11-07T23:05:05 IST">
          <exception class="java.lang.AssertionError">
            <message>
              <![CDATA[The following asserts failed:
expected [test] but found [test123]]]>
            </message>
            <full-stacktrace>
              <![CDATA[java.lang.AssertionError: The following asserts failed:
expected [test] but found [test123]
at org.testng.asserts.SoftAssert.assertAll(SoftAssert.java:47)
at org.testng.asserts.SoftAssert.assertAll(SoftAssert.java:31)
at week4.day4.LearnTestNGAssert.testCase1(LearnTestNGAssert.java:15)
at sun.reflect.NativeMethodAccessorImpl.invoke0(Native Method)
at sun.reflect.NativeMethodAccessorImpl.invoke(Unknown Source)
at sun.reflect.DelegatingMethodAccessorImpl.invoke(Unknown Source)
at java.lang.reflect.Method.invoke(Unknown Source)
at org.testng.internal.MethodInvocationHelper.invokeMethod(MethodInvocationHelper.java:133)
at org.testng.internal.TestInvoker.invokeMethod(TestInvoker.java:584)
at org.testng.internal.TestInvoker.invokeTestMethod(TestInvoker.java:172)
at org.testng.internal.MethodRunner.runInSequence(MethodRunner.java:46)
at org.testng.internal.TestInvoker$MethodInvocationAgent.invoke(TestInvoker.java:804)
at org.testng.internal.TestInvoker.invokeTestMethods(TestInvoker.java:145)
at org.testng.internal.TestMethodWorker.invokeTestMethods(TestMethodWorker.java:146)
at org.testng.internal.TestMethodWorker.run(TestMethodWorker.java:128)
at java.util.ArrayList.forEach(Unknown Source)
at org.testng.TestRunner.privateRun(TestRunner.java:770)
at org.testng.TestRunner.run(TestRunner.java:591)
at org.testng.SuiteRunner.runTest(SuiteRunner.java:402)
at org.testng.SuiteRunner.runSequentially(SuiteRunner.java:396)
at org.testng.SuiteRunner.privateRun(SuiteRunner.java:355)
at org.testng.SuiteRunner.run(SuiteRunner.java:304)
at org.testng.SuiteRunnerWorker.runSuite(SuiteRunnerWorker.java:53)
at org.testng.SuiteRunnerWorker.run(SuiteRunnerWorker.java:96)
at org.testng.TestNG.runSuitesSequentially(TestNG.java:1180)
at org.testng.TestNG.runSuitesLocally(TestNG.java:1102)
at org.testng.TestNG.runSuites(TestNG.java:1032)
at org.testng.TestNG.run(TestNG.java:1000)
at org.testng.remote.AbstractRemoteTestNG.run(AbstractRemoteTestNG.java:115)
at org.testng.remote.RemoteTestNG.initAndRun(RemoteTestNG.java:251)
at org.testng.remote.RemoteTestNG.main(RemoteTestNG.java:77)
]]>
            </full-stacktrace>
          </exception> <!-- java.lang.AssertionError -->
          <reporter-output>
          </reporter-output>
        </test-method> <!-- testCase1 -->
        <test-method status="PASS" signature="testCase2()[pri:0, instance:week4.day4.LearnTestNGAssert@b8a058]" name="testCase2" duration-ms="11" started-at="2019-11-07T23:05:05 IST" finished-at="2019-11-07T23:05:05 IST">
          <reporter-output>
          </reporter-output>
        </test-method> <!-- testCase2 -->
        <test-method status="PASS" signature="testCase3()[pri:0, instance:week4.day4.LearnTestNGAssert@b8a058]" name="testCase3" duration-ms="4" started-at="2019-11-07T23:05:05 IST" finished-at="2019-11-07T23:05:05 IST">
          <reporter-output>
          </reporter-output>
        </test-method> <!-- testCase3 -->
      </class> <!-- week4.day4.LearnTestNGAssert -->
    </test> <!-- Default test -->
  </suite> <!-- Default suite -->
</testng-results>
